<?xml version="1.0"?>
<robot name="two_leaf_door">
  <material name="wood_paint">
    <color rgba="0.6235 0.6196 0.4980 1.0"/>
  </material>
  <material name="handle_silver">
    <color rgba="0.78 0.78 0.78 1.0"/>
  </material>
  <material name="panel_black">
    <color rgba="0.05 0.05 0.05 1.0"/>
  </material>

  <link name="door_frame">
    <visual>
      <origin xyz="0 0 0" rpy="0 0 0"/>
      <geometry>
        <mesh filename="meshes/door_frame.stl" scale="1 1 1"/>
      </geometry>
      <material name="wood_paint"/>
    </visual>
    <!-- Collision disabled for door frame -->
    <!--
    <collision>
      <origin xyz="0 0 0" rpy="0 0 0"/>
      <geometry>
        <mesh filename="meshes/door_frame.stl" scale="1 1 1"/>
      </geometry>
    </collision>
    -->
    <inertial>
      <origin xyz="0.5334 0 0.5207" rpy="0 0 0"/>
      <mass value="3.0"/>
      <inertia ixx="0.27177365" ixy="0" ixz="0" iyy="0.55564405" iyz="0" izz="0.28516072"/>
    </inertial>
  </link>

  <link name="left_wing">
    <visual>
      <origin xyz="0 0 0" rpy="0 0 0"/>
      <geometry>
        <mesh filename="meshes/left_wing.stl" scale="1 1 1"/>
      </geometry>
      <material name="wood_paint"/>
    </visual>
    <collision>
      <origin xyz="0 0 0" rpy="0 0 0"/>
      <geometry>
        <mesh filename="meshes/left_wing.stl" scale="1 1 1"/>
      </geometry>
    </collision>
    <visual>
      <!-- Black box spanning 1/3 to 5/6 height, 3x connector width, flush on outer face -->
      <origin xyz="0.45 -0.0279 0.65" rpy="0 0 0"/>
      <geometry>
        <box size="0.1 0.005 0.4"/>
      </geometry>
      <material name="panel_black"/>
    </visual>
    <collision>
      <origin xyz="0.45 -0.0279 0.65" rpy="0 0 0"/>
      <geometry>
        <box size="0.1 0.005 0.4"/>
      </geometry>
    </collision>
    <inertial>
      <origin xyz="0.3048 0 0.4826" rpy="0 0 0"/>
      <mass value="5.0"/>
      <inertia ixx="0.38924653" ixy="0" ixz="0" iyy="0.54300967" iyz="0" izz="0.15591367"/>
    </inertial>
  </link>

  <link name="right_wing">
    <visual>
      <origin xyz="0 0 0" rpy="0 0 0"/>
      <geometry>
        <mesh filename="meshes/right_wing.stl" scale="1 1 1"/>
      </geometry>
      <material name="wood_paint"/>
    </visual>
    <collision>
      <origin xyz="0 0 0" rpy="0 0 0"/>
      <geometry>
        <mesh filename="meshes/right_wing.stl" scale="1 1 1"/>
      </geometry>
    </collision>
    <inertial>
      <origin xyz="0.762 0 0.4826" rpy="0 0 0"/>
      <mass value="2.5"/>
      <inertia ixx="0.19462327" ixy="0" ixz="0" iyy="0.21344043" iyz="0" izz="0.01989243"/>
    </inertial>
  </link>

  <link name="left_handle">
    <visual>
      <!-- Thin rectangular connector; joint is at 1/3 height from its bottom edge, standing vertical and flush to the door -->
      <origin xyz="0 -0.0025 0.02" rpy="0 0 0"/>
      <geometry>
        <box size="0.04 0.005 0.12"/>
      </geometry>
      <material name="handle_silver"/>
    </visual>
    <visual>
      <origin xyz="0 -0.0304 0" rpy="1.5708 0 0"/>
      <geometry>
        <cylinder radius="0.01" length="0.05"/>
      </geometry>
      <material name="handle_silver"/>
    </visual>
    <visual>
      <origin xyz="-0.06 -0.0554 0" rpy="0 1.5708 0"/>
      <geometry>
        <cylinder radius="0.01" length="0.12"/>
      </geometry>
      <material name="handle_silver"/>
    </visual>
    <collision>
      <origin xyz="0 -0.0025 0.02" rpy="0 0 0"/>
      <geometry>
        <box size="0.04 0.005 0.12"/>
      </geometry>
    </collision>
    <collision>
      <origin xyz="0 -0.0304 0" rpy="1.5708 0 0"/>
      <geometry>
        <cylinder radius="0.01" length="0.05"/>
      </geometry>
    </collision>
    <collision>
      <origin xyz="-0.06 -0.0554 0" rpy="0 1.5708 0"/>
      <geometry>
        <cylinder radius="0.01" length="0.12"/>
      </geometry>
    </collision>
    <inertial>
      <origin xyz="-0.03 0.03 0" rpy="0 0 0"/>
      <mass value="0.2"/>
      <inertia ixx="1e-4" ixy="0" ixz="0" iyy="1e-4" iyz="0" izz="1e-4"/>
    </inertial>
  </link>

  <joint name="left_hinge" type="revolute">
    <parent link="door_frame"/>
    <child link="left_wing"/>
    <origin xyz="0 0 0" rpy="0 0 0"/>
    <axis xyz="0 0 1"/>
    <limit lower="-1.5708" upper="0" effort="30" velocity="2.0"/>
    <dynamics damping="2.0" friction="0.5"/>
  </joint>

  <joint name="right_fixed" type="fixed">
    <parent link="door_frame"/>
    <child link="right_wing"/>
    <origin xyz="0 0 0" rpy="0 0 0"/>
  </joint>

  <joint name="left_handle_joint" type="revolute">
    <parent link="left_wing"/>
    <child link="left_handle"/>
    <origin xyz="0.5588 -0.0254 0.3861" rpy="0 0 0"/>
    <axis xyz="0 1 0"/>
    <limit lower="-1.5708" upper="0" effort="5" velocity="2.0"/>
    <dynamics damping="0.5" friction="0.1"/>
  </joint>
</robot>
